<mujoco model="1x1_ur5e_Spheres">

  <statistic extent="1.5" meansize=".05"/>

  <size memory="1G"/>

  <option timestep="0.005" solver="CG" integrator="implicit"/>

  <visual>
    <rgba haze="0.15 0.25 0.35 1"/>
    <map shadowscale="0.5" zfar="40"/>
  </visual>

  <asset>
    <texture type="skybox" builtin="gradient" rgb1="0.3 0.5 0.7" rgb2="0 0 0" width="64" height="64"/>
    <texture name="texplane" type="2d" builtin="checker" rgb1=".2 .3 .4" rgb2=".1 0.15 0.2" width="512" height="512" mark="cross" markrgb=".8 .8 .8"/>
    <material name="matplane" reflectance="0.3" texture="texplane" texrepeat="1 1" texuniform="true"/>
    <!-- Load ur5e model for attach -->
    <model name="ur5e" file="ur5e.xml"/>
  </asset>

  <worldbody>
    <light directional="true" diffuse=".4 .4 .4" specular="0.1 0.1 0.1" pos="0 0 5" castshadow="false"/>
    <light diffuse=".6 .6 .6" specular="0.2 0.2 0.2" pos="0 0 4"/>

    <geom name="ground" type="plane" size="0 0 1" pos="0 0 0" quat="1 0 0 0" material="matplane" condim="1"/>

    <!-- UR5e robotic arm -->
    <frame pos="0 0 0">
      <attach model="ur5e" body="base" prefix="u0_"/>
    </frame>

    <!-- Pit walls -->
    <replicate count="4" euler="0 0 1.5708">
      <geom type="plane" size=".5 .5 .05" zaxis="1 0 0"  pos="-.5 0 -.25"/>
    </replicate>

    <!-- Particles (red spheres) -->
    <replicate count="10" offset=".07 0 0">
      <replicate count="10" offset="0 .07 0">
        <replicate count="10" offset="0 0 .07">
          <body pos="-0.35 -0.35 0.65">
            <joint type="slide" axis="1 0 0" group="3"/>
            <joint type="slide" axis="0 1 0" group="3"/>
            <joint type="slide" axis="0 0 1" group="3"/>
            <geom size="0.025" condim="1" priority="1" rgba="0.8 0.2 0.1 1"/>
          </body>
        </replicate>
      </replicate>
    </replicate>
  </worldbody>

</mujoco>
