<mujoco model="3x3_ur5e_Shapes_NoCylinder">

  <include file="3x3_ur5e_container.xml"/>

  <size memory="2G"/>

  <option solver="CG" tolerance="1e-6" timestep=".01"/>

  <worldbody>
    <!-- Particle group 1 (red spheres) - above u0 at (-2, -2) -->
    <replicate count="10" offset=".18 0 0">
      <replicate count="10" offset="0 .18 0">
        <replicate count="10" offset="0 0 .18">
          <body pos="-2.81 -2.81 1.3">
            <joint type="slide" axis="1 0 0" group="3"/>
            <joint type="slide" axis="0 1 0" group="3"/>
            <joint type="slide" axis="0 0 1" group="3"/>
            <geom type="sphere" size="0.05" condim="1" priority="1" rgba="0.8 0.2 0.1 1"/>
          </body>
        </replicate>
      </replicate>
    </replicate>

    <!-- Particle group 2 (green boxes) - above u1 at (0, -2) -->
    <replicate count="10" offset=".18 0 0">
      <replicate count="10" offset="0 .18 0">
        <replicate count="10" offset="0 0 .18">
          <body pos="-0.81 -2.81 1.3">
            <joint type="slide" axis="1 0 0" group="3"/>
            <joint type="slide" axis="0 1 0" group="3"/>
            <joint type="slide" axis="0 0 1" group="3"/>
            <geom type="box" size="0.04 0.04 0.04" condim="1" priority="1" rgba="0.2 0.8 0.2 1"/>
          </body>
        </replicate>
      </replicate>
    </replicate>

    <!-- Particle group 3 (blue ellipsoids) - above u2 at (2, -2) -->
    <replicate count="10" offset=".18 0 0">
      <replicate count="10" offset="0 .18 0">
        <replicate count="10" offset="0 0 .18">
          <body pos="1.19 -2.81 1.3">
            <joint type="slide" axis="1 0 0" group="3"/>
            <joint type="slide" axis="0 1 0" group="3"/>
            <joint type="slide" axis="0 0 1" group="3"/>
            <geom type="ellipsoid" size="0.04 0.03 0.05" condim="1" priority="1" rgba="0.2 0.4 0.9 1"/>
          </body>
        </replicate>
      </replicate>
    </replicate>

    <!-- Particle group 4 (yellow capsules) - above u3 at (-2, 0) -->
    <replicate count="10" offset=".18 0 0">
      <replicate count="10" offset="0 .18 0">
        <replicate count="10" offset="0 0 .18">
          <body pos="-2.81 -0.81 1.3">
            <joint type="slide" axis="1 0 0" group="3"/>
            <joint type="slide" axis="0 1 0" group="3"/>
            <joint type="slide" axis="0 0 1" group="3"/>
            <geom type="capsule" size="0.03 0.04" condim="1" priority="1" rgba="0.9 0.8 0.2 1"/>
          </body>
        </replicate>
      </replicate>
    </replicate>

    <!-- Particle group 5 (purple ellipsoids) - above u4 at (0, 0) -->
    <replicate count="10" offset=".18 0 0">
      <replicate count="10" offset="0 .18 0">
        <replicate count="10" offset="0 0 .18">
          <body pos="-0.81 -0.81 1.3">
            <joint type="slide" axis="1 0 0" group="3"/>
            <joint type="slide" axis="0 1 0" group="3"/>
            <joint type="slide" axis="0 0 1" group="3"/>
            <geom type="ellipsoid" size="0.05 0.04 0.03" condim="1" priority="1" rgba="0.7 0.2 0.8 1"/>
          </body>
        </replicate>
      </replicate>
    </replicate>

    <!-- Particle group 6 (cyan spheres) - above u5 at (2, 0) -->
    <replicate count="10" offset=".18 0 0">
      <replicate count="10" offset="0 .18 0">
        <replicate count="10" offset="0 0 .18">
          <body pos="1.19 -0.81 1.3">
            <joint type="slide" axis="1 0 0" group="3"/>
            <joint type="slide" axis="0 1 0" group="3"/>
            <joint type="slide" axis="0 0 1" group="3"/>
            <geom type="sphere" size="0.05" condim="1" priority="1" rgba="0.2 0.8 0.9 1"/>
          </body>
        </replicate>
      </replicate>
    </replicate>

    <!-- Particle group 7 (orange boxes) - above u6 at (-2, 2) -->
    <replicate count="10" offset=".18 0 0">
      <replicate count="10" offset="0 .18 0">
        <replicate count="10" offset="0 0 .18">
          <body pos="-2.81 1.19 1.3">
            <joint type="slide" axis="1 0 0" group="3"/>
            <joint type="slide" axis="0 1 0" group="3"/>
            <joint type="slide" axis="0 0 1" group="3"/>
            <geom type="box" size="0.04 0.04 0.04" condim="1" priority="1" rgba="0.9 0.5 0.1 1"/>
          </body>
        </replicate>
      </replicate>
    </replicate>

    <!-- Particle group 8 (pink capsules) - above u7 at (0, 2) -->
    <replicate count="10" offset=".18 0 0">
      <replicate count="10" offset="0 .18 0">
        <replicate count="10" offset="0 0 .18">
          <body pos="-0.81 1.19 1.3">
            <joint type="slide" axis="1 0 0" group="3"/>
            <joint type="slide" axis="0 1 0" group="3"/>
            <joint type="slide" axis="0 0 1" group="3"/>
            <geom type="capsule" size="0.03 0.04" condim="1" priority="1" rgba="0.9 0.4 0.6 1"/>
          </body>
        </replicate>
      </replicate>
    </replicate>

    <!-- Particle group 9 (white spheres) - above u8 at (2, 2) -->
    <replicate count="10" offset=".18 0 0">
      <replicate count="10" offset="0 .18 0">
        <replicate count="10" offset="0 0 .18">
          <body pos="1.19 1.19 1.3">
            <joint type="slide" axis="1 0 0" group="3"/>
            <joint type="slide" axis="0 1 0" group="3"/>
            <joint type="slide" axis="0 0 1" group="3"/>
            <geom type="sphere" size="0.05" condim="1" priority="1" rgba="0.9 0.9 0.9 1"/>
          </body>
        </replicate>
      </replicate>
    </replicate>
  </worldbody>

</mujoco>
